<?xml version="1.0" ?>
<!-- =================================================================================== -->
<!-- |    This document was autogenerated by xacro from sisbot.xacro                   | -->
<!-- |    EDITING THIS FILE BY HAND IS NOT RECOMMENDED                                 | -->
<!-- =================================================================================== -->
<robot name="ur5e_robotiq_2f140" xmlns:xacro="http://ros.org/wiki/xacro">
  <!--################################################
  ########              arm                    #######
  ####################################################-->

  <link name="base_link">
    <visual>
      <geometry>
        <mesh filename="ur5e/visual/base.dae"/>
      </geometry>
      <material name="LightGrey">
        <color rgba="0.7 0.7 0.7 1.0"/>
      </material>
    </visual>
    <collision>
      <geometry>
        <mesh filename="ur5e/collision/base.stl" scale="1.0 1.0 1.0"/>
      </geometry>
    </collision>
    <inertial>
      <mass value="4.0"/>
      <origin rpy="0 0 0" xyz="0.0 0.0 0.0"/>
      <inertia ixx="0.00443333156" ixy="0.0" ixz="0.0" iyy="0.00443333156" iyz="0.0" izz="0.0072"/>
    </inertial>
  </link>
  <joint name="shoulder_pan_joint" type="revolute">
    <parent link="base_link"/>
    <child link="shoulder_link"/>
    <origin rpy="0.0 0.0 0.0" xyz="0.0 0.0 0.163"/>
    <axis xyz="0 0 1"/>
    <limit effort="150.0" lower="-6.28318530718" upper="6.28318530718" velocity="3.14"/>
    <dynamics damping="0.0" friction="0.0"/>
  </joint>
  <link name="shoulder_link">
    <visual>
      <geometry>
        <mesh filename="ur5e/visual/shoulder.dae"/>
      </geometry>
      <material name="LightGrey">
        <color rgba="0.7 0.7 0.7 1.0"/>
      </material>
    </visual>
    <collision>
      <geometry>
        <mesh filename="ur5e/collision/shoulder.stl" scale="1.0 1.0 1.0"/>
      </geometry>
    </collision>
    <inertial>
      <mass value="3.7"/>
      <origin rpy="0 0 0" xyz="0.0 0.0 0.0"/>
      <inertia ixx="0.010267495893" ixy="0.0" ixz="0.0" iyy="0.010267495893" iyz="0.0" izz="0.00666"/>
    </inertial>
  </link>
  <joint name="shoulder_lift_joint" type="revolute">
    <parent link="shoulder_link"/>
    <child link="upper_arm_link"/>
    <origin rpy="0.0 1.57079632679 0.0" xyz="0.0 0.138 0.0"/>
    <axis xyz="0 1 0"/>
    <limit effort="150.0" lower="-6.28318530718" upper="6.28318530718" velocity="3.14"/>
    <dynamics damping="0.0" friction="0.0"/>
  </joint>
  <link name="upper_arm_link">
    <visual>
      <geometry>
        <mesh filename="ur5e/visual/upperarm.dae"/>
      </geometry>
      <material name="LightGrey">
        <color rgba="0.7 0.7 0.7 1.0"/>
      </material>
    </visual>
    <collision>
      <geometry>
        <mesh filename="ur5e/collision/upperarm.stl" scale="1.0 1.0 1.0"/>
      </geometry>
    </collision>
    <inertial>
      <mass value="8.393"/>
      <origin rpy="0 0 0" xyz="0.0 0.0 0.2125"/>
      <inertia ixx="0.133885781862" ixy="0.0" ixz="0.0" iyy="0.133885781862" iyz="0.0" izz="0.0151074"/>
    </inertial>
  </link>
  <joint name="elbow_joint" type="revolute">
    <parent link="upper_arm_link"/>
    <child link="forearm_link"/>
    <origin rpy="0.0 0.0 0.0" xyz="0.0 -0.131 0.425"/>
    <axis xyz="0 1 0"/>
    <limit effort="150.0" lower="-3.14159265359" upper="3.14159265359" velocity="3.14"/>
    <dynamics damping="0.0" friction="0.0"/>
  </joint>
  <link name="forearm_link">
    <visual>
      <geometry>
        <mesh filename="ur5e/visual/forearm.dae"/>
      </geometry>
      <material name="LightGrey">
        <color rgba="0.7 0.7 0.7 1.0"/>
      </material>
    </visual>
    <collision>
      <geometry>
        <mesh filename="ur5e/collision/forearm.stl" scale="1.0 1.0 1.0"/>
      </geometry>
    </collision>
    <inertial>
      <mass value="2.275"/>
      <origin rpy="0 0 0" xyz="0.0 0.0 0.196"/>
      <inertia ixx="0.0311796208615" ixy="0.0" ixz="0.0" iyy="0.0311796208615" iyz="0.0" izz="0.004095"/>
    </inertial>
  </link>
  <joint name="wrist_1_joint" type="revolute">
    <parent link="forearm_link"/>
    <child link="wrist_1_link"/>
    <origin rpy="0.0 1.57079632679 0.0" xyz="0.0 0.0 0.392"/>
    <axis xyz="0 1 0"/>
    <limit effort="28.0" lower="-6.28318530718" upper="6.28318530718" velocity="6.28"/>
    <dynamics damping="0.0" friction="0.0"/>
  </joint>
  <link name="wrist_1_link">
    <visual>
      <geometry>
        <mesh filename="ur5e/visual/wrist1.dae"/>
      </geometry>
      <material name="LightGrey">
        <color rgba="0.7 0.7 0.7 1.0"/>
      </material>
    </visual>
    <collision>
      <geometry>
        <mesh filename="ur5e/collision/wrist1.stl" scale="1.0 1.0 1.0"/>
      </geometry>
    </collision>
    <inertial>
      <mass value="1.219"/>
      <origin rpy="0 0 0" xyz="0.0 0.127 0.0"/>
      <inertia ixx="0.00255989897604" ixy="0.0" ixz="0.0" iyy="0.00255989897604" iyz="0.0" izz="0.0021942"/>
    </inertial>
  </link>
  <joint name="wrist_2_joint" type="revolute">
    <parent link="wrist_1_link"/>
    <child link="wrist_2_link"/>
    <origin rpy="0.0 0.0 0.0" xyz="0.0 0.127 0.0"/>
    <axis xyz="0 0 1"/>
    <limit effort="28.0" lower="-6.28318530718" upper="6.28318530718" velocity="6.28"/>
    <dynamics damping="0.0" friction="0.0"/>
  </joint>
  <link name="wrist_2_link">
    <visual>
      <geometry>
        <mesh filename="ur5e/visual/wrist2.dae"/>
      </geometry>
      <material name="LightGrey">
        <color rgba="0.7 0.7 0.7 1.0"/>
      </material>
    </visual>
    <collision>
      <geometry>
        <mesh filename="ur5e/collision/wrist2.stl" scale="1.0 1.0 1.0"/>
      </geometry>
    </collision>
    <inertial>
      <mass value="1.219"/>
      <origin rpy="0 0 0" xyz="0.0 0.0 0.1"/>
      <inertia ixx="0.00255989897604" ixy="0.0" ixz="0.0" iyy="0.00255989897604" iyz="0.0" izz="0.0021942"/>
    </inertial>
  </link>
  <joint name="wrist_3_joint" type="revolute">
    <parent link="wrist_2_link"/>
    <child link="wrist_3_link"/>
    <origin rpy="0.0 0.0 0.0" xyz="0.0 0.0 0.1"/>
    <axis xyz="0 1 0"/>
    <limit effort="28.0" lower="-6.28318530718" upper="6.28318530718" velocity="6.28"/>
    <dynamics damping="0.0" friction="0.0"/>
  </joint>
  <link name="wrist_3_link">
    <visual>
      <geometry>
        <mesh filename="ur5e/visual/wrist3.dae"/>
      </geometry>
      <material name="LightGrey">
        <color rgba="0.7 0.7 0.7 1.0"/>
      </material>
    </visual>
    <collision>
      <geometry>
        <mesh filename="ur5e/collision/wrist3.stl" scale="1.0 1.0 1.0"/>
      </geometry>
    </collision>
    <inertial>
      <mass value="0.1879"/>
      <origin rpy="1.57079632679 0 0" xyz="0.0 0.0771 0.0"/>
      <inertia ixx="9.89041005217e-05" ixy="0.0" ixz="0.0" iyy="9.89041005217e-05" iyz="0.0" izz="0.0001321171875"/>
    </inertial>
  </link>
  <joint name="ee_fixed_joint" type="fixed">
    <parent link="wrist_3_link"/>
    <child link="ee_link"/>
    <origin rpy="0.0 0.0 1.57079632679" xyz="0.0 0.1 0.0"/>
  </joint>
  <link name="ee_link">
    <inertial>
      <origin rpy="0 0 0" xyz="0 0 0"/>
      <mass value="0.0"/>
      <inertia ixx="1" ixy="0" ixz="0" iyy="1" iyz="0" izz="1"/>
    </inertial>
    <collision>
      <geometry>
        <box size="0.01 0.01 0.01"/>
      </geometry>
      <origin rpy="0 0 0" xyz="-0.01 0 0"/>
    </collision>
  </link>

  <!--################################################
  ########              gripper                  #####
  ####################################################-->

 <link name="2f140_base_link">
    <inertial>
      <origin rpy="0 0 0" xyz="-0.00013 0.00011 0.03284"/>
      <mass value="0.52954"/>
      <inertia ixx="573495E-9" ixy="-554E-9" ixz="2628E-9" iyy="681780E-9" iyz="607E-9" izz="483281E-9"/>
    </inertial>
    <visual>
      <origin rpy="0 0 0" xyz="0 0 0"/>
      <geometry>
        <mesh filename="2f140/visual/2f140_base.dae" scale="0.001 0.001 0.001"/>
      </geometry>
      <material name="Black">
        <color rgba="0.2 0.2 0.2 1" />
      </material>
    </visual>
    <collision>
      <origin rpy="0 0 0" xyz="0 0 0"/>
      <geometry>
        <mesh filename="2f140/collision/2f140_base.dae" scale="0.001 0.001 0.001"/>
      </geometry>
    </collision>
  </link>
  <link name="2f140_left_outer_knuckle">
    <inertial>
      <origin rpy="0 0 0" xyz="0.01616 0 -0.00133"/>
      <mass value="0.0131"/>
      <inertia ixx="325.5E-9" ixy="0" ixz="197.94E-9" iyy="2306.36E-9" iyz="0" izz="2176E-9"/>
    </inertial>
    <visual>
      <origin rpy="0 0 0" xyz="0 0 0"/>
      <geometry>
        <mesh filename="2f140/visual/2f140_left_outer_knuckle.dae" scale="0.001 0.001 0.001"/>
      </geometry>
      <material name="">
        <color rgba="0.792156862745098 0.819607843137255 0.933333333333333 1"/>
      </material>
    </visual>
    <collision>
      <origin rpy="0 0 0" xyz="0 0 0"/>
      <geometry>
        <mesh filename="2f140/collision/2f140_left_outer_knuckle.dae" scale="0.001 0.001 0.001"/>
      </geometry>
    </collision>
  </link>
  <link name="2f140_right_outer_knuckle">
    <inertial>
      <origin rpy="0 0 0" xyz="-0.01616 0 -0.00133"/>
      <mass value="0.0131"/>
      <inertia ixx="325.5E-9" ixy="0" ixz="-197.94E-9" iyy="2306.36E-9" iyz="0" izz="2176E-9"/>
    </inertial>
    <visual>
      <origin rpy="0 0 0" xyz="0 0 0"/>
      <geometry>
        <mesh filename="2f140/visual/2f140_right_outer_knuckle.dae" scale="0.001 0.001 0.001"/>
      </geometry>
      <material name="">
        <color rgba="0.792156862745098 0.819607843137255 0.933333333333333 1"/>
      </material>
    </visual>
    <collision>
      <origin rpy="0 0 0" xyz="0 0 0"/>
      <geometry>
        <mesh filename="2f140/collision/2f140_right_outer_knuckle.dae" scale="0.001 0.001 0.001"/>
      </geometry>
    </collision>
  </link>
  <link name="2f140_left_inner_knuckle">
    <inertial>
      <origin rpy="0 0 0" xyz="0.03332 0 0.0379"/>
      <mass value="0.04476"/>
      <inertia ixx="28054E-9" ixy="0" ixz="-19174E-9" iyy="39758E-9" iyz="0" izz="23453E-9"/>
    </inertial>
    <visual>
      <origin rpy="0 0 0" xyz="0 0 0"/>
      <geometry>
        <mesh filename="2f140/visual/2f140_left_inner_knuckle.dae" scale="0.001 0.001 0.001"/>
      </geometry>
      <material name="">
        <color rgba="0.792156862745098 0.819607843137255 0.933333333333333 1"/>
      </material>
    </visual>
    <collision>
      <origin rpy="0 0 0" xyz="0 0 0"/>
      <geometry>
        <mesh filename="2f140/collision/2f140_left_inner_knuckle.dae" scale="0.001 0.001 0.001"/>
      </geometry>
    </collision>
  </link>
  <link name="2f140_right_inner_knuckle">
    <inertial>
      <origin rpy="0 0 0" xyz="-0.03332 0 0.0379"/>
      <mass value="0.04476"/>
      <inertia ixx="28054E-9" ixy="0" ixz="19174E-9" iyy="39758E-9" iyz="0" izz="23453E-9"/>
    </inertial>
    <visual>
      <origin rpy="0 0 0" xyz="0 0 0"/>
      <geometry>
        <mesh filename="2f140/visual/2f140_right_inner_knuckle.dae" scale="0.001 0.001 0.001"/>
      </geometry>
      <material name="Gazebo/Black">
        <color rgba="0.1 0.1 0.1 1"/>
      </material>
    </visual>
    <collision>
      <origin rpy="0 0 0" xyz="0 0 0"/>
      <geometry>
        <mesh filename="2f140/collision/2f140_right_inner_knuckle.dae" scale="0.001 0.001 0.001"/>
      </geometry>
    </collision>
  </link>
  <link name="2f140_left_inner_finger">
    <inertial>
      <origin rpy="0 0 0" xyz="-0.01563 0 0.02522"/>
      <mass value="0.045"/>
      <inertia ixx="26663E-9" ixy="0" ixz="5579E-9" iyy="28009E-9" iyz="0" izz="4368E-9"/>
    </inertial>
    <visual>
      <origin rpy="0 0 0" xyz="0 0 0"/>
      <geometry>
        <mesh filename="2f140/visual/2f140_left_inner_finger.dae" scale="0.001 0.001 0.001"/>
      </geometry>
      <material name="">
        <color rgba="0.792156862745098 0.819607843137255 0.933333333333333 1"/>
      </material>
    </visual>
    <collision>
      <origin rpy="0 0 0" xyz="0 0 0"/>
      <geometry>
        <mesh filename="2f140/collision/2f140_left_inner_finger.dae" scale="0.001 0.001 0.001"/>
      </geometry>
    </collision>
  </link>
  <link name="2f140_right_inner_finger">
    <inertial>
      <origin rpy="0 0 0" xyz="0.01563 0 0.02522"/>
      <mass value="0.045"/>
      <inertia ixx="26663E-9" ixy="0" ixz="-5579E-9" iyy="28009E-9" iyz="0" izz="4368E-9"/>
    </inertial>
    <visual>
      <origin rpy="0 0 0" xyz="0 0 0"/>
      <geometry>
        <mesh filename="2f140/visual/2f140_right_inner_finger.dae" scale="0.001 0.001 0.001"/>
      </geometry>
      <material name="Gazebo/Black">
        <color rgba="0.1 0.1 0.1 1"/>
      </material>
    </visual>
    <collision>
      <origin rpy="0 0 0" xyz="0 0 0"/>
      <geometry>
        <mesh filename="2f140/collision/2f140_right_inner_finger.dae" scale="0.001 0.001 0.001"/>
      </geometry>
    </collision>
  </link>
  <link name="2f140_left_outer_finger">
    <inertial>
      <origin rpy="0 0 0" xyz="0.01482 0 0.03451"/>
      <mass value="0.07637"/>
      <inertia ixx="45513E-9" ixy="0" ixz="-20691E-9" iyy="52570E-9" iyz="0" izz="17804E-9"/>
    </inertial>
    <visual>
      <origin rpy="0 0 0" xyz="0 0 0"/>
      <geometry>
        <mesh filename="2f140/visual/2f140_left_outer_finger.dae" scale="0.001 0.001 0.001"/>
      </geometry>
      <material name="Gazebo/Black">
        <color rgba="0.1 0.1 0.1 1"/>
      </material>
    </visual>
    <collision>
      <origin rpy="0 0 0" xyz="0 0 0"/>
      <geometry>
        <mesh filename="2f140/collision/2f140_left_outer_finger.dae" scale="0.001 0.001 0.001"/>
      </geometry>
    </collision>
  </link>
  <link name="2f140_right_outer_finger">
    <inertial>
      <origin rpy="0 0 0" xyz="-0.01482 0 0.03451"/>
      <mass value="0.07637"/>
      <inertia ixx="45513E-9" ixy="0" ixz="20691E-9" iyy="52570E-9" iyz="0" izz="17804E-9"/>
    </inertial>
    <visual>
      <origin rpy="0 0 0" xyz="0 0 0"/>
      <geometry>
        <mesh filename="2f140/visual/2f140_right_outer_finger.dae" scale="0.001 0.001 0.001"/>
      </geometry>
      <material name="Gazebo/Black">
        <color rgba="0.1 0.1 0.1 1"/>
      </material>
    </visual>
    <collision>
      <origin rpy="0 0 0" xyz="0 0 0"/>
      <geometry>
        <mesh filename="2f140/collision/2f140_right_outer_finger.dae" scale="0.001 0.001 0.001"/>
      </geometry>
    </collision>
  </link>

  <joint name="2f140_base_to_left_outer_knuckle" type="revolute">
    <origin rpy="0 0 0" xyz="0.0306 0 0.05466"/>
    <parent link="2f140_base_link"/>
    <child link="2f140_left_outer_knuckle"/>
    <axis xyz="0 -1 0"/>
    <limit effort="18.65" lower="0" upper="0.78574722925" velocity="2.0"/>
    <mimic joint="2f140_joint_finger" multiplier="1" offset="0"/>
  </joint>
  <joint name="2f140_joint_finger" type="revolute">
    <origin rpy="0 0 0" xyz="-0.0306 0 0.05466"/>
    <parent link="2f140_base_link"/>
    <child link="2f140_right_outer_knuckle"/>
    <axis xyz="0 1 0"/>
    <limit effort="18.65" lower="0" upper="0.78574722925" velocity="3.54"/>
  </joint>
  <joint name="2f140_base_to_left_inner_knuckle" type="revolute">
    <origin rpy="0 0 0" xyz="0.0127 0 0.06118"/>
    <parent link="2f140_base_link"/>
    <child link="2f140_left_inner_knuckle"/>
    <axis xyz="0 -1 0"/>
    <limit effort="18.65" lower="0" upper="0.78574722925" velocity="3.54"/>
    <mimic joint="2f140_joint_finger" multiplier="1" offset="0"/>
  </joint>
  <joint name="2f140_base_to_right_inner_knuckle" type="revolute">
    <origin rpy="0 0 0" xyz="-0.0127 0 0.06118"/>
    <parent link="2f140_base_link"/>
    <child link="2f140_right_inner_knuckle"/>
    <axis xyz="0 1 0"/>
    <limit effort="18.65" lower="0" upper="0.78574722925" velocity="3.54"/>
    <mimic joint="2f140_joint_finger" multiplier="1" offset="0"/>
  </joint>
  <joint name="2f140_left_outer_knuckle_to_finger" type="fixed">
    <origin rpy="0 0 0" xyz="0.03142 0 -0.00453"/>
    <parent link="2f140_left_outer_knuckle"/>
    <child link="2f140_left_outer_finger"/>
  </joint>
  <joint name="2f140_right_outer_knuckle_to_finger" type="fixed">
    <origin rpy="0 0 0" xyz="-0.03142 0 -0.00453"/>
    <parent link="2f140_right_outer_knuckle"/>
    <child link="2f140_right_outer_finger"/>
  </joint>
  <joint name="2f140_left_outer_finger_to_inner" type="revolute">
    <origin rpy="0 0 0" xyz="0.03543 0 0.0789"/>
    <parent link="2f140_left_outer_finger"/>
    <child link="2f140_left_inner_finger"/>
    <axis xyz="0 1 0"/>
    <limit effort="18.65" lower="0" upper="0.78574722925" velocity="3.54"/>
    <mimic joint="2f140_joint_finger" multiplier="1" offset="0"/>
  </joint>
  <joint name="2f140_right_outer_finger_to_inner" type="revolute">
    <origin rpy="0 0 0" xyz="-0.03543 0 0.0789"/>
    <parent link="2f140_right_outer_finger"/>
    <child link="2f140_right_inner_finger"/>
    <axis xyz="0 -1 0"/>
    <limit effort="18.65" lower="0" upper="0.78574722925" velocity="3.54"/>
    <mimic joint="2f140_joint_finger" multiplier="1" offset="0"/>
  </joint>


  <!--################################################
  ########          connect model                #####
  ####################################################-->

  <link name="world"/>
  <!-- connect gripper to arm -->
  <joint name="arm_gripper_joint" type="fixed">
    <parent link="ee_link"/>
    <child link="2f140_base_link"/>
    <origin rpy="-1.57 0 -1.57" xyz="0.0 0.0 0.0"/>
  </joint>

  <!-- connect arm to world -->
  <joint name="world_arm_joint" type="fixed">
    <parent link="world"/>
    <child link="base_link"/>
    <origin rpy="0.0 0.0 0" xyz="0 0 0"/>
  </joint>

</robot>

